2018-10-09 18:09:01,792 p=22946 u=mford |   [WARNING]: While constructing a mapping from /Users/mford/Documents/github-workspace/mpoc/netscaler-poc/netscaler-test.yml, line 8,
column 5, found a duplicate dict key (name). Using last defined value only.

2018-10-09 18:09:02,026 p=22946 u=mford |  ERROR! 'servicetype' is not a valid attribute for a Task

The error appears to have been in '/Users/mford/Documents/github-workspace/mpoc/netscaler-poc/netscaler-test.yml': line 8, column 5, but may
be elsewhere in the file depending on the exact syntax problem.

The offending line appears to be:


  - name: configure the “management” vrf
    ^ here

This error can be suppressed as a warning using the "invalid_task_attribute_failed" configuration
2018-10-09 18:09:39,683 passlib.registry registered 'md5_crypt' handler: <class 'passlib.handlers.md5_crypt.md5_crypt'>
2018-10-09 18:09:39,689 p=22964 u=mford |  PLAY [netscaler] *************************************************************************************************************************
2018-10-09 18:09:39,703 p=22964 u=mford |  TASK [configure the “management” vrf] ****************************************************************************************************
2018-10-09 18:09:40,904 p=22971 u=mford |  shutdown complete
2018-10-09 18:09:41,450 p=22964 u=mford |  fatal: [54.236.219.70]: FAILED! => {"msg": "Unable to automatically determine host network os. Please manually configure ansible_network_os value for this host"}
2018-10-09 18:09:41,453 p=22964 u=mford |  	to retry, use: --limit @/Users/mford/Documents/github-workspace/mpoc/netscaler-poc/netscaler-test.retry

2018-10-09 18:09:41,453 p=22964 u=mford |  PLAY RECAP *******************************************************************************************************************************
2018-10-09 18:09:41,454 p=22964 u=mford |  54.236.219.70              : ok=0    changed=0    unreachable=0    failed=1   
2018-10-09 18:12:11,844 passlib.registry registered 'md5_crypt' handler: <class 'passlib.handlers.md5_crypt.md5_crypt'>
2018-10-09 18:12:11,851 p=23002 u=mford |  PLAY [netscaler] *************************************************************************************************************************
2018-10-09 18:12:11,864 p=23002 u=mford |  TASK [configure the “management” vrf] ****************************************************************************************************
2018-10-09 18:12:12,989 p=23002 u=mford |  fatal: [54.236.219.70]: UNREACHABLE! => {"changed": false, "msg": "Authentication or permission failure. In some cases, you may have been able to authenticate and did not have permissions on the target directory. Consider changing the remote tmp path in ansible.cfg to a path rooted in \"/tmp\". Failed command was: ( umask 77 && mkdir -p \"` echo ERROR: No such command/.ansible/tmp/ansible-tmp-1539123131.96-162477463949555 `\" && echo ansible-tmp-1539123131.96-162477463949555=\"` echo ERROR: No such command/.ansible/tmp/ansible-tmp-1539123131.96-162477463949555 `\" ), exited with result 1, stdout output:  Done\nERROR: No such command\n", "unreachable": true}
2018-10-09 18:12:12,991 p=23002 u=mford |  	to retry, use: --limit @/Users/mford/Documents/github-workspace/mpoc/netscaler-poc/netscaler-test.retry

2018-10-09 18:12:12,992 p=23002 u=mford |  PLAY RECAP *******************************************************************************************************************************
2018-10-09 18:12:12,992 p=23002 u=mford |  54.236.219.70              : ok=0    changed=0    unreachable=1    failed=0   
2018-10-09 18:12:28,414 passlib.registry registered 'md5_crypt' handler: <class 'passlib.handlers.md5_crypt.md5_crypt'>
2018-10-09 18:12:28,420 p=23016 u=mford |  PLAY [netscaler] *************************************************************************************************************************
2018-10-09 18:12:28,432 p=23016 u=mford |  TASK [configure the “management” vrf] ****************************************************************************************************
2018-10-09 18:12:28,892 p=23016 u=mford |  fatal: [54.236.219.70]: UNREACHABLE! => {"changed": false, "msg": "Authentication or permission failure. In some cases, you may have been able to authenticate and did not have permissions on the target directory. Consider changing the remote tmp path in ansible.cfg to a path rooted in \"/tmp\". Failed command was: ( umask 77 && mkdir -p \"` echo ERROR: No such command/.ansible/tmp/ansible-tmp-1539123148.53-125599760259207 `\" && echo ansible-tmp-1539123148.53-125599760259207=\"` echo ERROR: No such command/.ansible/tmp/ansible-tmp-1539123148.53-125599760259207 `\" ), exited with result 1, stdout output:  Done\nERROR: No such command\n", "unreachable": true}
2018-10-09 18:12:28,894 p=23016 u=mford |  	to retry, use: --limit @/Users/mford/Documents/github-workspace/mpoc/netscaler-poc/netscaler-test.retry

2018-10-09 18:12:28,895 p=23016 u=mford |  PLAY RECAP *******************************************************************************************************************************
2018-10-09 18:12:28,895 p=23016 u=mford |  54.236.219.70              : ok=0    changed=0    unreachable=1    failed=0   
2018-10-09 18:13:55,142 passlib.registry registered 'md5_crypt' handler: <class 'passlib.handlers.md5_crypt.md5_crypt'>
2018-10-09 18:13:55,149 p=23037 u=mford |  PLAY [netscaler] *************************************************************************************************************************
2018-10-09 18:13:55,163 p=23037 u=mford |  TASK [configure the “management” vrf] ****************************************************************************************************
2018-10-09 18:13:56,262 p=23037 u=mford |  fatal: [54.236.219.70]: UNREACHABLE! => {"changed": false, "msg": "Authentication or permission failure. In some cases, you may have been able to authenticate and did not have permissions on the target directory. Consider changing the remote tmp path in ansible.cfg to a path rooted in \"/tmp\". Failed command was: ( umask 77 && mkdir -p \"` echo ERROR: No such command/.ansible/tmp/ansible-tmp-1539123235.26-219857909769879 `\" && echo ansible-tmp-1539123235.26-219857909769879=\"` echo ERROR: No such command/.ansible/tmp/ansible-tmp-1539123235.26-219857909769879 `\" ), exited with result 1, stdout output:  Done\nERROR: No such command\n", "unreachable": true}
2018-10-09 18:13:56,264 p=23037 u=mford |  	to retry, use: --limit @/Users/mford/Documents/github-workspace/mpoc/netscaler-poc/netscaler-test.retry

2018-10-09 18:13:56,264 p=23037 u=mford |  PLAY RECAP *******************************************************************************************************************************
2018-10-09 18:13:56,265 p=23037 u=mford |  54.236.219.70              : ok=0    changed=0    unreachable=1    failed=0   
2018-10-09 18:14:51,949 passlib.registry registered 'md5_crypt' handler: <class 'passlib.handlers.md5_crypt.md5_crypt'>
2018-10-09 18:14:51,955 p=23056 u=mford |  PLAY [netscaler] *************************************************************************************************************************
2018-10-09 18:14:51,971 p=23056 u=mford |  TASK [configure the “management” vrf] ****************************************************************************************************
2018-10-09 18:14:52,458 p=23056 u=mford |  fatal: [54.236.219.70]: UNREACHABLE! => {"changed": false, "msg": "Authentication or permission failure. In some cases, you may have been able to authenticate and did not have permissions on the target directory. Consider changing the remote tmp path in ansible.cfg to a path rooted in \"/tmp\". Failed command was: ( umask 77 && mkdir -p \"` echo ERROR: No such command/.ansible/tmp/ansible-tmp-1539123292.1-56317601865500 `\" && echo ansible-tmp-1539123292.1-56317601865500=\"` echo ERROR: No such command/.ansible/tmp/ansible-tmp-1539123292.1-56317601865500 `\" ), exited with result 1, stdout output:  Done\nERROR: No such command\n", "unreachable": true}
2018-10-09 18:14:52,460 p=23056 u=mford |  	to retry, use: --limit @/Users/mford/Documents/github-workspace/mpoc/netscaler-poc/netscaler-test.retry

2018-10-09 18:14:52,461 p=23056 u=mford |  PLAY RECAP *******************************************************************************************************************************
2018-10-09 18:14:52,461 p=23056 u=mford |  54.236.219.70              : ok=0    changed=0    unreachable=1    failed=0   
2018-10-09 18:17:16,981 p=23090 u=mford |  ansible-playbook 2.7.0
  config file = /Users/mford/Documents/github-workspace/mpoc/netscaler-poc/ansible.cfg
  configured module search path = [u'/Users/mford/.ansible/plugins/modules', u'/usr/share/ansible/plugins/modules']
  ansible python module location = /Library/Python/2.7/site-packages/ansible
  executable location = /usr/local/bin/ansible-playbook
  python version = 2.7.10 (default, Oct  6 2017, 22:29:07) [GCC 4.2.1 Compatible Apple LLVM 9.0.0 (clang-900.0.31)]
2018-10-09 18:17:16,982 p=23090 u=mford |  Using /Users/mford/Documents/github-workspace/mpoc/netscaler-poc/ansible.cfg as config file
2018-10-09 18:17:17,675 p=23090 u=mford |  PLAYBOOK: netscaler-test.yml *************************************************************************************************************
2018-10-09 18:17:17,675 p=23090 u=mford |  1 plays in netscaler-test.yml
2018-10-09 18:17:17,713 passlib.registry registered 'md5_crypt' handler: <class 'passlib.handlers.md5_crypt.md5_crypt'>
2018-10-09 18:17:17,719 p=23090 u=mford |  PLAY [netscaler] *************************************************************************************************************************
2018-10-09 18:17:17,723 p=23090 u=mford |  META: ran handlers
2018-10-09 18:17:17,733 p=23090 u=mford |  TASK [Add HTTP Service] ******************************************************************************************************************
2018-10-09 18:17:17,734 p=23090 u=mford |  task path: /Users/mford/Documents/github-workspace/mpoc/netscaler-poc/netscaler-test.yml:7
2018-10-09 18:17:18,843 p=23090 u=mford |  fatal: [54.236.219.70]: UNREACHABLE! => {"changed": false, "msg": "Authentication or permission failure. In some cases, you may have been able to authenticate and did not have permissions on the target directory. Consider changing the remote tmp path in ansible.cfg to a path rooted in \"/tmp\". Failed command was: ( umask 77 && mkdir -p \"` echo ERROR: No such command/.ansible/tmp/ansible-tmp-1539123437.84-112334696455139 `\" && echo ansible-tmp-1539123437.84-112334696455139=\"` echo ERROR: No such command/.ansible/tmp/ansible-tmp-1539123437.84-112334696455139 `\" ), exited with result 1, stdout output:  Done\nERROR: No such command\n", "unreachable": true}
2018-10-09 18:17:18,852 p=23090 u=mford |  	to retry, use: --limit @/Users/mford/Documents/github-workspace/mpoc/netscaler-poc/netscaler-test.retry

2018-10-09 18:17:18,853 p=23090 u=mford |  PLAY RECAP *******************************************************************************************************************************
2018-10-09 18:17:18,853 p=23090 u=mford |  54.236.219.70              : ok=0    changed=0    unreachable=1    failed=0   
